2023-03-08 17:17:22,978 INFO    StreamThr :22948 [internal.py:wandb_internal():90] W&B internal server running at pid: 22948, started at: 2023-03-08 17:17:22.976610
2023-03-08 17:17:22,980 DEBUG   HandlerThread:22948 [handler.py:handle_request():144] handle_request: status
2023-03-08 17:17:22,986 INFO    WriterThread:22948 [datastore.py:open_for_write():85] open: /home/daniel/Repos/Mujoco_Python_Sandbox/value_gradient/wandb/run-20230308_171722-nklzkg1u/run-nklzkg1u.wandb
2023-03-08 17:17:22,988 DEBUG   SenderThread:22948 [sender.py:send():336] send: header
2023-03-08 17:17:23,034 DEBUG   SenderThread:22948 [sender.py:send():336] send: run
2023-03-08 17:17:24,668 ERROR   SenderThread:22948 [internal_api.py:execute():245] 403 response executing GraphQL.
2023-03-08 17:17:24,669 ERROR   SenderThread:22948 [internal_api.py:execute():246] {"errors":[{"message":"permission denied","path":["upsertBucket"],"extensions":{"code":"PERMISSION_ERROR"}}],"data":{"upsertBucket":null}}
2023-03-08 17:17:24,669 ERROR   SenderThread:22948 [sender.py:send_run():931] It appears that you do not have permission to access the requested resource. Please reach out to the project owner to grant you access. If you have the correct permissions, verify that there are no issues with your networking setup.(Error 403: Forbidden)
Traceback (most recent call last):
  File "/home/daniel/.local/share/virtualenvs/Mujoco_Python_Sandbox-gNKKWzd6/lib/python3.7/site-packages/wandb/sdk/lib/retry.py", line 131, in __call__
    result = self._call_fn(*args, **kwargs)
  File "/home/daniel/.local/share/virtualenvs/Mujoco_Python_Sandbox-gNKKWzd6/lib/python3.7/site-packages/wandb/sdk/internal/internal_api.py", line 242, in execute
    return self.client.execute(*args, **kwargs)  # type: ignore
  File "/home/daniel/.local/share/virtualenvs/Mujoco_Python_Sandbox-gNKKWzd6/lib/python3.7/site-packages/wandb/vendor/gql-0.2.0/wandb_gql/client.py", line 52, in execute
    result = self._get_result(document, *args, **kwargs)
  File "/home/daniel/.local/share/virtualenvs/Mujoco_Python_Sandbox-gNKKWzd6/lib/python3.7/site-packages/wandb/vendor/gql-0.2.0/wandb_gql/client.py", line 60, in _get_result
    return self.transport.execute(document, *args, **kwargs)
  File "/home/daniel/.local/share/virtualenvs/Mujoco_Python_Sandbox-gNKKWzd6/lib/python3.7/site-packages/wandb/vendor/gql-0.2.0/wandb_gql/transport/requests.py", line 39, in execute
    request.raise_for_status()
  File "/home/daniel/.local/share/virtualenvs/Mujoco_Python_Sandbox-gNKKWzd6/lib/python3.7/site-packages/requests/models.py", line 1021, in raise_for_status
    raise HTTPError(http_error_msg, response=self)
requests.exceptions.HTTPError: 403 Client Error: Forbidden for url: https://api.wandb.ai/graphql

During handling of the above exception, another exception occurred:

Traceback (most recent call last):
  File "/home/daniel/.local/share/virtualenvs/Mujoco_Python_Sandbox-gNKKWzd6/lib/python3.7/site-packages/wandb/sdk/internal/sender.py", line 929, in send_run
    self._init_run(run, config_value_dict)
  File "/home/daniel/.local/share/virtualenvs/Mujoco_Python_Sandbox-gNKKWzd6/lib/python3.7/site-packages/wandb/sdk/internal/sender.py", line 982, in _init_run
    commit=run.git.commit or None,
  File "/home/daniel/.local/share/virtualenvs/Mujoco_Python_Sandbox-gNKKWzd6/lib/python3.7/site-packages/wandb/apis/normalize.py", line 51, in wrapper
    raise err
  File "/home/daniel/.local/share/virtualenvs/Mujoco_Python_Sandbox-gNKKWzd6/lib/python3.7/site-packages/wandb/apis/normalize.py", line 25, in wrapper
    return func(*args, **kwargs)
  File "/home/daniel/.local/share/virtualenvs/Mujoco_Python_Sandbox-gNKKWzd6/lib/python3.7/site-packages/wandb/sdk/internal/internal_api.py", line 1592, in upsert_run
    **kwargs,
  File "/home/daniel/.local/share/virtualenvs/Mujoco_Python_Sandbox-gNKKWzd6/lib/python3.7/site-packages/wandb/sdk/internal/internal_api.py", line 217, in gql
    **kwargs,
  File "/home/daniel/.local/share/virtualenvs/Mujoco_Python_Sandbox-gNKKWzd6/lib/python3.7/site-packages/wandb/sdk/lib/retry.py", line 147, in __call__
    retry_timedelta_triggered = check_retry_fn(e)
  File "/home/daniel/.local/share/virtualenvs/Mujoco_Python_Sandbox-gNKKWzd6/lib/python3.7/site-packages/wandb/util.py", line 1091, in check_retry_fn
    return fallback_retry_fn(e)
  File "/home/daniel/.local/share/virtualenvs/Mujoco_Python_Sandbox-gNKKWzd6/lib/python3.7/site-packages/wandb/util.py", line 1034, in no_retry_auth
    "It appears that you do not have permission to access the requested resource. "
wandb.errors.CommError: It appears that you do not have permission to access the requested resource. Please reach out to the project owner to grant you access. If you have the correct permissions, verify that there are no issues with your networking setup.(Error 403: Forbidden)
2023-03-08 17:17:24,687 DEBUG   HandlerThread:22948 [handler.py:handle_request():144] handle_request: shutdown
2023-03-08 17:17:24,688 INFO    HandlerThread:22948 [handler.py:finish():842] shutting down handler
2023-03-08 17:17:25,034 INFO    WriterThread:22948 [datastore.py:close():298] close: /home/daniel/Repos/Mujoco_Python_Sandbox/value_gradient/wandb/run-20230308_171722-nklzkg1u/run-nklzkg1u.wandb
2023-03-08 17:17:25,673 INFO    SenderThread:22948 [sender.py:finish():1504] shutting down sender
